<?xml version='1.0' encoding='UTF-8'?>
<mujoco model="scutl_stairs">
  <default>
    <geom material="robot_green"/>
  </default>
  <option timestep="0.004" gravity="0 0 -9.84"/>
  <visual>
    <global offwidth="1920" offheight="1080"/>
  </visual>
  <asset>
    <texture name="grid" type="2d" builtin="checker" rgb1=".1 .2 .3" rgb2=".2 .3 .4" width="300" height="300"/>
    <texture name="stair_tex" type="2d" builtin="checker" rgb1=".4 .4 .4" rgb2=".6 .6 .6" width="100" height="100"/>
    <material name="grid" texture="grid" texrepeat="30 30" reflectance="0"/>
    <material name="stair_mat" texture="stair_tex" texrepeat="2 2" reflectance="0.1"/>
    <material name="robot_green" rgba="0.1 0.35 0.1 1"/>
    <texture name="wood_tex" type="2d" builtin="checker" rgb1=".55 .40 .25" rgb2=".45 .32 .18" width="100" height="100"/>
    <material name="wood" texture="wood_tex" texrepeat="4 1" reflectance="0.05"/>
  </asset>
  <default>
    <default class="robot">
      <geom material="robot_green" condim="6" friction="1.5 0.05 0.01"/>
    </default>
    <default class="stair">
      <geom type="box" material="stair_mat" condim="6" friction="1.5 0.05 0.01"/>
    </default>
    <default class="joist">
      <geom type="box" material="wood" condim="6" friction="1.5 0.05 0.01"/>
    </default>
  </default>
  <worldbody>
    <light name="strong_light" pos="0 0 5" dir="0 0 -4" directional="true" diffuse="1 1 4" specular="0.3 0.3 0.6" active="true" castshadow="false" cutoff="100" exponent="10"/>

    <!-- flat approach ground -->
    <geom name="ground" type="plane" pos="0 0 -2.12" size="10 10 0.4" material="grid" condim="6" friction="1.5 0.05 0.01"/>

    <!-- staircase: 8 steps, each 0.04m rise, 0.12m run, 0.3m wide -->
    <!-- step 1 -->
    <geom class="stair" name="step1" size="0.06 0.45 0.02" pos="0.12 0.36184 -2.10"/>
    <!-- step 2 -->
    <geom class="stair" name="step2" size="0.06 0.45 0.06" pos="0.24 0.36184 -2.08"/>
    <!-- step 3 -->
    <geom class="stair" name="step3" size="0.06 0.45 0.1" pos="0.36 0.36184 -2.06"/>
    <!-- step 4 -->
    <geom class="stair" name="step4" size="0.06 0.45 0.14" pos="0.48 0.36184 -2.04"/>
    <!-- step 5 -->
    <geom class="stair" name="step5" size="0.06 0.45 0.18" pos="0.60 0.36184 -2.02"/>
    <!-- step 6 -->
    <geom class="stair" name="step6" size="0.06 0.45 0.22" pos="0.72 0.36184 -2.00"/>
    <!-- step 7 -->
    <geom class="stair" name="step7" size="0.06 0.45 0.26" pos="0.84 0.36184 -1.98"/>
    <!-- step 8 -->
    <geom class="stair" name="step8" size="0.06 0.45 0.30" pos="0.96 0.36184 -1.96"/>
    <!-- landing platform at top -->
    <geom class="stair" name="landing" size="0.30 0.45 0.30" pos="1.38 0.36184 -1.96"/>

    <geom class="joist" name="joist0" size="0.0254 0.6096 0.0762" pos="-4.0320 0.35 -2.0438"/>
    <geom class="joist" name="joist1" size="0.0254 0.6096 0.0762" pos="-3.6256 0.35 -2.0438"/>
    <geom class="joist" name="joist2" size="0.0254 0.6096 0.0762" pos="-3.2192 0.35 -2.0438"/>
    <geom class="joist" name="joist3" size="0.0254 0.6096 0.0762" pos="-2.8128 0.35 -2.0438"/>
    <geom class="joist" name="joist4" size="0.0254 0.6096 0.0762" pos="-2.4064 0.35 -2.0438"/>
    <geom class="joist" name="joist5" size="0.0254 0.6096 0.0762" pos="-2.0000 0.35 -2.0438"/>
    <geom class="joist" name="joist6" size="0.0254 0.6096 0.0762" pos="-1.5936 0.35 -2.0438"/>
    <geom class="joist" name="joist7" size="0.0254 0.6096 0.0762" pos="-1.1872 0.35 -2.0438"/>
    <geom class="joist" name="joist8" size="0.0254 0.6096 0.0762" pos="-0.7808 0.35 -2.0438"/>
    <geom class="joist" name="joist9" size="0.0254 0.6096 0.0762" pos="-0.3744 0.35 -2.0438"/>





    <geom class="stair" name="step11" size="0.06 0.45 0.02" pos="2.61 0.36184 -2.10" euler="0 0 180"/>
    <!-- step 2 -->
    <geom class="stair" name="step21" size="0.06 0.45 0.06" pos="2.49 0.36184 -2.08" euler="0 0 180"/>
    <!-- step 3 -->
    <geom class="stair" name="step31" size="0.06 0.45 0.1" pos="2.37 0.36184 -2.06" euler="0 0 180"/>
    <!-- step 4 -->
    <geom class="stair" name="step41" size="0.06 0.45 0.14" pos="2.25 0.36184 -2.04" euler="0 0 180"/>
    <!-- step 5 -->
    <geom class="stair" name="step51" size="0.06 0.45 0.18" pos="2.13 0.36184 -2.02" euler="0 0 180"/>
    <!-- step 6 -->
    <geom class="stair" name="step61" size="0.06 0.45 0.22" pos="2.01 0.36184 -2.00" euler="0 0 180"/>
    <!-- step 7 -->
    <geom class="stair" name="step71" size="0.06 0.45 0.26" pos="1.89 0.36184 -1.98" euler="0 0 180"/>
    <!-- step 8 -->
    <geom class="stair" name="step81" size="0.06 0.45 0.30" pos="1.77 0.36184 -1.96" euler="0 0 180"/>

    
    <!-- landing platform at top -->

    <!-- ===== ROBOT ===== -->
    <body name="body_middle6" pos="-5.00714 0.23184 0.008" euler="0 0 90">
      <joint name="root_free" type="free"/>
      <geom size="0.0666575 0.041973 0.0374445" pos="0.074417 0.12845 0.025525" type="box" rgba="0.4 0.6 0.8 1"/>
      <inertial pos="0.074417 0.12845 0.025525" mass="0.08684000" diaginertia="0.00009158204 0.00016920278 0.00017961293"/>

      <body name="motor_L6" pos="0 0 0">
        <inertial pos="0.13525 0.12938 0.022634" mass="0.04388000" diaginertia="0.00000721932 0.00001081797 0.00001232792"/>
        <geom size="0.009 0.012 0.0215" pos="0.13525 0.12938 0.022634" type="box" rgba="0.3 0.3 0.3 1"/>
        <body name="o_leg_L6" pos="0 0 0">
          <joint name="knee_joint_L6" type="hinge" pos="-0.009764 0.1294 0.01076" axis="1 0 0" damping="0.5"/>
          <inertial pos="0.16407 0.12939 -0.027134" mass="0.10587964" diaginertia="0.00004860956 0.00005124607 0.00009533636"/>
          <geom name="o_leg_L6" size="0.045 0.006" pos="0.16407 0.12939 -0.027134" quat="0.707105 0 0.707108 0" type="cylinder" rgba="0.8 0.4 0.2 1"/>
        </body>
      </body>

      <body name="motor_R6" pos="0 0 0">
        <inertial pos="0.012712 0.12941 0.022604" mass="0.04388000" diaginertia="0.00000721932 0.00001081797 0.00001232792"/>
        <geom size="0.009 0.012 0.0215" pos="0.012712 0.12941 0.022604" type="box" rgba="0.3 0.3 0.3 1"/>
        <body name="o_leg_R6" pos="0 0 0">
          <joint name="knee_joint_R6" type="hinge" pos="-0.009764 0.1294 0.01076" axis="1 0 0" damping="0.5"/>
          <inertial pos="-0.016106 0.1294 -0.027164" mass="0.10587964" diaginertia="0.00004860956 0.00005124607 0.00009533636"/>
          <geom name="o_leg_R6" size="0.045 0.006" pos="-0.016106 0.1294 -0.027164" quat="0.707105 0 0.707108 0" type="cylinder" rgba="0.8 0.4 0.2 1"/>
        </body>
      </body>

      <body name="vertjoint6" pos="0 0 0">
        <joint name="vertjoint_hinge6" type="hinge" pos="0.094905 0.086975 0.02858" axis="1 0 0" range="-90 90" damping="0.5"/>
        <inertial pos="0.077976 0.038797 0.027871" mass="0.15853000" diaginertia="0.00004786090 0.00019459966 0.00019531491"/>
        <geom size="0.018 0.0375" pos="0.077976 0.038797 0.027871" quat="0.499998 -0.500002 0.5 0.5" type="cylinder" rgba="0.5 0.5 0.5 1"/>

        <body name="horzjoint6_body" pos="0 0 0">
          <joint name="horzjoint6" type="hinge" pos="0.07753 -0.009025 0.045952" axis="0 0 1" range="-90 90" damping="0.5"/>
          <inertial pos="0.07753 -0.009025 0.045952" mass="0.0004" diaginertia="0.000001 0.000001 0.000001"/>

          <!-- ===== SECTION 2 ===== -->
          <body name="body_middle5" pos="0.00357 -0.18092 0.003">
            <geom size="0.0666575 0.041973 0.0374445" pos="0.074417 0.12845 0.025525" type="box" rgba="0.4 0.6 0.8 1"/>
            <inertial pos="0.074417 0.12845 0.025525" mass="0.08684000" diaginertia="0.00009158204 0.00016920278 0.00017961293"/>

            <body name="motor_L5" pos="0 0 0">
              <inertial pos="0.13525 0.12938 0.022634" mass="0.04388000" diaginertia="0.00000721932 0.00001081797 0.00001232792"/>
              <geom size="0.009 0.012 0.0215" pos="0.13525 0.12938 0.022634" type="box" rgba="0.3 0.3 0.3 1"/>
              <body name="o_leg_L5" pos="0 0 0">
                <joint name="knee_joint_L5" type="hinge" pos="-0.009764 0.1294 0.01076" axis="1 0 0" damping="0.5"/>
                <inertial pos="0.16407 0.12939 -0.027134" mass="0.10587964" diaginertia="0.00004860956 0.00005124607 0.00009533636"/>
                <geom name="o_leg_L5" size="0.045 0.006" pos="0.16407 0.12939 -0.027134" quat="0.707105 0 0.707108 0" type="cylinder" rgba="0.8 0.4 0.2 1"/>
              </body>
            </body>

            <body name="motor_R5" pos="0 0 0">
              <inertial pos="0.012712 0.12941 0.022604" mass="0.04388000" diaginertia="0.00000721932 0.00001081797 0.00001232792"/>
              <geom size="0.009 0.012 0.0215" pos="0.012712 0.12941 0.022604" type="box" rgba="0.3 0.3 0.3 1"/>
              <body name="o_leg_R5" pos="0 0 0">
                <joint name="knee_joint_R5" type="hinge" pos="-0.009764 0.1294 0.01076" axis="1 0 0" damping="0.5"/>
                <inertial pos="-0.016106 0.1294 -0.027164" mass="0.10587964" diaginertia="0.00004860956 0.00005124607 0.00009533636"/>
                <geom name="o_leg_R5" size="0.045 0.006" pos="-0.016106 0.1294 -0.027164" quat="0.707105 0 0.707108 0" type="cylinder" rgba="0.8 0.4 0.2 1"/>
              </body>
            </body>

            <body name="vertjoint5" pos="0 0 0">
              <joint name="vertjoint_hinge5" type="hinge" pos="0.094905 0.086975 0.02858" axis="1 0 0" range="-90 90" damping="0.5"/>
              <inertial pos="0.077976 0.038797 0.027871" mass="0.15853000" diaginertia="0.00004786090 0.00019459966 0.00019531491"/>
              <geom size="0.018 0.0375" pos="0.077976 0.038797 0.027871" quat="0.499998 -0.500002 0.5 0.5" type="cylinder" rgba="0.5 0.5 0.5 1"/>

              <body name="horzjoint5_body" pos="0 0 0">
                <joint name="horzjoint5" type="hinge" pos="0.07753 -0.009025 0.045952" axis="0 0 1" range="-90 90" damping="0.5"/>
                <inertial pos="0.07753 -0.009025 0.045952" mass="0.0004" diaginertia="0.000001 0.000001 0.000001"/>

                <!-- ===== SECTION 1 ===== -->
                <body name="body_middle4" pos="0.00357 -0.18092 0.003">
                  <geom size="0.0666575 0.041973 0.0374445" pos="0.074417 0.12845 0.025525" type="box" rgba="0.4 0.6 0.8 1"/>
                  <inertial pos="0.074417 0.12845 0.025525" mass="0.08684000" diaginertia="0.00009158204 0.00016920278 0.00017961293"/>

                  <body name="motor_L4" pos="0 0 0">
                    <inertial pos="0.13525 0.12938 0.022634" mass="0.04388000" diaginertia="0.00000721932 0.00001081797 0.00001232792"/>
                    <geom size="0.009 0.012 0.0215" pos="0.13525 0.12938 0.022634" type="box" rgba="0.3 0.3 0.3 1"/>
                    <body name="o_leg_L4" pos="0 0 0">
                      <joint name="knee_joint_L4" type="hinge" pos="-0.009764 0.1294 0.01076" axis="1 0 0" damping="0.5"/>
                      <inertial pos="0.16407 0.12939 -0.027134" mass="0.10587964" diaginertia="0.00004860956 0.00005124607 0.00009533636"/>
                      <geom name="o_leg_L4" size="0.045 0.006" pos="0.16407 0.12939 -0.027134" quat="0.707105 0 0.707108 0" type="cylinder" rgba="0.8 0.4 0.2 1"/>
                    </body>
                  </body>

                  <body name="motor_R4" pos="0 0 0">
                    <inertial pos="0.012712 0.12941 0.022604" mass="0.04388000" diaginertia="0.00000721932 0.00001081797 0.00001232792"/>
                    <geom size="0.009 0.012 0.0215" pos="0.012712 0.12941 0.022604" type="box" rgba="0.3 0.3 0.3 1"/>
                    <body name="o_leg_R4" pos="0 0 0">
                      <joint name="knee_joint_R4" type="hinge" pos="-0.009764 0.1294 0.01076" axis="1 0 0" damping="0.5"/>
                      <inertial pos="-0.016106 0.1294 -0.027164" mass="0.10587964" diaginertia="0.00004860956 0.00005124607 0.00009533636"/>
                      <geom name="o_leg_R4" size="0.045 0.006" pos="-0.016106 0.1294 -0.027164" quat="0.707105 0 0.707108 0" type="cylinder" rgba="0.8 0.4 0.2 1"/>
                    </body>
                  </body>

                  <body name="vertjoint4" pos="0 0 0">
                    <joint name="vertjoint_hinge4" type="hinge" pos="0.094905 0.086975 0.02858" axis="1 0 0" range="-90 90" damping="0.5"/>
                    <inertial pos="0.077976 0.038797 0.027871" mass="0.15853000" diaginertia="0.00004786090 0.00019459966 0.00019531491"/>
                    <geom size="0.018 0.0375" pos="0.077976 0.038797 0.027871" quat="0.499998 -0.500002 0.5 0.5" type="cylinder" rgba="0.5 0.5 0.5 1"/>

                    <body name="horzjoint4_body" pos="0 0 0">
                      <joint name="horzjoint4" type="hinge" pos="0.07753 -0.009025 0.045952" axis="0 0 1" range="-90 90" damping="0.5"/>
                      <inertial pos="0.07753 -0.009025 0.045952" mass="0.0004" diaginertia="0.000001 0.000001 0.000001"/>

                      <!-- ===== SECTION 4 ===== -->
                      <body name="body_middle3" pos="0.00357 -0.18092 0.003">
                        <camera name="robot_center_scene_camera" pos="0.074 0.064 0.120" xyaxes="-1 0 0 0 0 1" fovy="90"/>
                        <geom size="0.0666575 0.041973 0.0374445" pos="0.074417 0.12845 0.025525" type="box" rgba="0.4 0.7 0.4 1"/>
                        <inertial pos="0.074417 0.12845 0.025525" mass="0.08684000" diaginertia="0.00009158204 0.00016920278 0.00017961293"/>

                        <body name="motor_L3" pos="0 0 0">
                          <inertial pos="0.13525 0.12938 0.022634" mass="0.04388000" diaginertia="0.00000721932 0.00001081797 0.00001232792"/>
                          <geom size="0.009 0.012 0.0215" pos="0.13525 0.12938 0.022634" type="box" rgba="0.3 0.3 0.3 1"/>
                          <body name="o_leg_L3" pos="0 0 0">
                            <joint name="knee_joint_L3" type="hinge" pos="-0.009764 0.1294 0.01076" axis="1 0 0" damping="0.5"/>
                            <inertial pos="0.16407 0.12939 -0.027134" mass="0.10587964" diaginertia="0.00004860956 0.00005124607 0.00009533636"/>
                            <geom name="o_leg_L3" size="0.045 0.006" pos="0.16407 0.12939 -0.027134" quat="0.707105 0 0.707108 0" type="cylinder" rgba="0.8 0.4 0.2 1"/>
                          </body>
                        </body>

                        <body name="motor_R3" pos="0 0 0">
                          <inertial pos="0.012712 0.12941 0.022604" mass="0.04388000" diaginertia="0.00000721932 0.00001081797 0.00001232792"/>
                          <geom size="0.009 0.012 0.0215" pos="0.012712 0.12941 0.022604" type="box" rgba="0.3 0.3 0.3 1"/>
                          <body name="o_leg_R3" pos="0 0 0">
                            <joint name="knee_joint_R3" type="hinge" pos="-0.009764 0.1294 0.01076" axis="1 0 0" damping="0.5"/>
                            <inertial pos="-0.016106 0.1294 -0.027164" mass="0.10587964" diaginertia="0.00004860956 0.00005124607 0.00009533636"/>
                            <geom name="o_leg_R3" size="0.045 0.006" pos="-0.016106 0.1294 -0.027164" quat="0.707105 0 0.707108 0" type="cylinder" rgba="0.8 0.4 0.2 1"/>
                          </body>
                        </body>

                        <body name="vertjoint3" pos="0 0 0">
                          <joint name="vertjoint_hinge3" type="hinge" pos="0.094905 0.086975 0.02858" axis="1 0 0" range="-90 90" damping="0.5"/>
                          <inertial pos="0.077976 0.038797 0.027871" mass="0.15853000" diaginertia="0.00004786090 0.00019459966 0.00019531491"/>
                          <geom size="0.018 0.0375" pos="0.077976 0.038797 0.027871" quat="0.499998 -0.500002 0.5 0.5" type="cylinder" rgba="0.5 0.5 0.5 1"/>

                          <body name="horzjoint3_body" pos="0 0 0">
                            <joint name="horzjoint3" type="hinge" pos="0.07753 -0.009025 0.045952" axis="0 0 1" range="-90 90" damping="0.5"/>
                            <inertial pos="0.07753 -0.009025 0.045952" mass="0.0004" diaginertia="0.000001 0.000001 0.000001"/>

                            <!-- ===== SECTION 5 ===== -->
                            <body name="body_middle2" pos="0.00357 -0.18092 0.003">
                              <geom size="0.0666575 0.041973 0.0374445" pos="0.074417 0.12845 0.025525" type="box" rgba="0.4 0.6 0.8 1"/>
                              <inertial pos="0.074417 0.12845 0.025525" mass="0.08684000" diaginertia="0.00009158204 0.00016920278 0.00017961293"/>

                              <body name="motor_L2" pos="0 0 0">
                                <inertial pos="0.13525 0.12938 0.022634" mass="0.04388000" diaginertia="0.00000721932 0.00001081797 0.00001232792"/>
                                <geom size="0.009 0.012 0.0215" pos="0.13525 0.12938 0.022634" type="box" rgba="0.3 0.3 0.3 1"/>
                                <body name="o_leg_L2" pos="0 0 0">
                                  <joint name="knee_joint_L2" type="hinge" pos="-0.009764 0.1294 0.01076" axis="1 0 0" damping="0.5"/>
                                  <inertial pos="0.16407 0.12939 -0.027134" mass="0.10587964" diaginertia="0.00004860956 0.00005124607 0.00009533636"/>
                                  <geom name="o_leg_L2" size="0.045 0.006" pos="0.16407 0.12939 -0.027134" quat="0.707105 0 0.707108 0" type="cylinder" rgba="0.8 0.4 0.2 1"/>
                                </body>
                              </body>

                              <body name="motor_R2" pos="0 0 0">
                                <inertial pos="0.012712 0.12941 0.022604" mass="0.04388000" diaginertia="0.00000721932 0.00001081797 0.00001232792"/>
                                <geom size="0.009 0.012 0.0215" pos="0.012712 0.12941 0.022604" type="box" rgba="0.3 0.3 0.3 1"/>
                                <body name="o_leg_R2" pos="0 0 0">
                                  <joint name="knee_joint_R2" type="hinge" pos="-0.009764 0.1294 0.01076" axis="1 0 0" damping="0.5"/>
                                  <inertial pos="-0.016106 0.1294 -0.027164" mass="0.10587964" diaginertia="0.00004860956 0.00005124607 0.00009533636"/>
                                  <geom name="o_leg_R2" size="0.045 0.006" pos="-0.016106 0.1294 -0.027164" quat="0.707105 0 0.707108 0" type="cylinder" rgba="0.8 0.4 0.2 1"/>
                                </body>
                              </body>

                              <body name="vertjoint2" pos="0 0 0">
                                <joint name="vertjoint_hinge2" type="hinge" pos="0.094905 0.086975 0.02858" axis="1 0 0" range="-90 90" damping="0.5"/>
                                <inertial pos="0.077976 0.038797 0.027871" mass="0.15853000" diaginertia="0.00004786090 0.00019459966 0.00019531491"/>
                                <geom size="0.018 0.0375" pos="0.077976 0.038797 0.027871" quat="0.499998 -0.500002 0.5 0.5" type="cylinder" rgba="0.5 0.5 0.5 1"/>

                                <body name="horzjoint2_body" pos="0 0 0">
                                  <joint name="horzjoint2" type="hinge" pos="0.07753 -0.009025 0.045952" axis="0 0 1" range="-90 90" damping="0.5"/>
                                  <inertial pos="0.07753 -0.009025 0.045952" mass="0.0004" diaginertia="0.000001 0.000001 0.000001"/>

                                  <!-- ===== SECTION 6 (tail) ===== -->
                                  <body name="body_middle1" pos="0.00357 -0.18092 0.003">
                                    <geom size="0.0666575 0.041973 0.0374445" pos="0.074417 0.12845 0.025525" type="box" rgba="0.4 0.6 0.8 1"/>
                                    <inertial pos="0.074417 0.12845 0.025525" mass="0.08684000" diaginertia="0.00009158204 0.00016920278 0.00017961293"/>

                                    <body name="motor_L1" pos="0 0 0">
                                      <inertial pos="0.13525 0.12938 0.022634" mass="0.04388000" diaginertia="0.00000721932 0.00001081797 0.00001232792"/>
                                      <geom size="0.009 0.012 0.0215" pos="0.13525 0.12938 0.022634" type="box" rgba="0.3 0.3 0.3 1"/>
                                      <body name="o_leg_L1" pos="0 0 0">
                                        <joint name="knee_joint_L1" type="hinge" pos="-0.009764 0.1294 0.01076" axis="1 0 0" damping="0.5"/>
                                        <inertial pos="0.16407 0.12939 -0.027134" mass="0.10587964" diaginertia="0.00004860956 0.00005124607 0.00009533636"/>
                                        <geom name="o_leg_L1" size="0.045 0.006" pos="0.16407 0.12939 -0.027134" quat="0.707105 0 0.707108 0" type="cylinder" rgba="0.8 0.4 0.2 1"/>
                                      </body>
                                    </body>

                                    <body name="motor_R1" pos="0 0 0">
                                      <inertial pos="0.012712 0.12941 0.022604" mass="0.04388000" diaginertia="0.00000721932 0.00001081797 0.00001232792"/>
                                      <geom size="0.009 0.012 0.0215" pos="0.012712 0.12941 0.022604" type="box" rgba="0.3 0.3 0.3 1"/>
                                      <body name="o_leg_R1" pos="0 0 0">
                                        <joint name="knee_joint_R1" type="hinge" pos="-0.009764 0.1294 0.01076" axis="1 0 0" damping="0.5"/>
                                        <inertial pos="-0.016106 0.1294 -0.027164" mass="0.10587964" diaginertia="0.00004860956 0.00005124607 0.00009533636"/>
                                        <geom name="o_leg_R1" size="0.045 0.006" pos="-0.016106 0.1294 -0.027164" quat="0.707105 0 0.707108 0" type="cylinder" rgba="0.8 0.4 0.2 1"/>
                                      </body>
                                    </body>

                                  </body>
                                </body>
                              </body>
                            </body>
                          </body>
                        </body>
                      </body>
                    </body>
                  </body>
                </body>
              </body>
            </body>
          </body>
        </body>
      </body>
    </body>
  </worldbody>

  <actuator>
    <position name="knee_L6" joint="knee_joint_L6" kp="10" forcerange="-4 4"/>
    <position name="knee_R6" joint="knee_joint_R6" kp="10" forcerange="-4 4"/>
    <position name="vertjoint6" joint="vertjoint_hinge6" ctrlrange="-100 100" kp="10" forcerange="-5 5"/>
    <position name="horzjoint6" joint="horzjoint6" ctrlrange="-100 100" kp="10"/>
    <position name="knee_L5" joint="knee_joint_L5" kp="10" forcerange="-4 4"/>
    <position name="knee_R5" joint="knee_joint_R5" kp="10" forcerange="-4 4"/>
    <position name="vertjoint5" joint="vertjoint_hinge5" ctrlrange="-100 100" kp="10" forcerange="-5 5"/>
    <position name="horzjoint5" joint="horzjoint5" ctrlrange="-100 100" kp="10"/>
    <position name="knee_L4" joint="knee_joint_L4" kp="10" forcerange="-4 4"/>
    <position name="knee_R4" joint="knee_joint_R4" kp="10" forcerange="-4 4"/>
    <position name="vertjoint4" joint="vertjoint_hinge4" ctrlrange="-100 100" kp="10" forcerange="-5 5"/>
    <position name="horzjoint4" joint="horzjoint4" ctrlrange="-100 100" kp="10"/>
    <position name="knee_L3" joint="knee_joint_L3" kp="10" forcerange="-4 4"/>
    <position name="knee_R3" joint="knee_joint_R3" kp="10" forcerange="-4 4"/>
    <position name="vertjoint3" joint="vertjoint_hinge3" ctrlrange="-100 100" kp="10" forcerange="-5 5"/>
    <position name="horzjoint3" joint="horzjoint3" ctrlrange="-100 100" kp="10"/>
    <position name="knee_L2" joint="knee_joint_L2" kp="10" forcerange="-4 4"/>
    <position name="knee_R2" joint="knee_joint_R2" kp="10" forcerange="-4 4"/>
    <position name="vertjoint2" joint="vertjoint_hinge2" ctrlrange="-100 100" kp="10" forcerange="-5 5"/>
    <position name="horzjoint2" joint="horzjoint2" ctrlrange="-100 100" kp="10"/>
    <position name="knee_L1" joint="knee_joint_L1" kp="10" forcerange="-4 4"/>
    <position name="knee_R1" joint="knee_joint_R1" kp="10" forcerange="-4 4"/>
  </actuator>
</mujoco>
